Workbook

Sheet Units
A2: Orc Light Infantry
A3: Movement | B3: Melee Ability | C3: Ranged Ability | D3: Defence | E3: Morale | F3: Wounds | G3: Mod | H3: Qty
A4: 7 | B4: 4 | C4: 10 | D4: 6 | E4: 6 | F4: 2
A5: =A4 -> 7 | B5: =10-B4 -> 6 | C5: =10-C4 -> 0 | D5: =10-D4 -> 4 | E5: =10-E4 -> 4 | F5: =F4 -> 2
A6: =A5*G6 -> 7 | B6: =B5*G6 -> 6 | C6: =C5*G6 -> 0 | D6: =D5*G6 -> 4 | E6: =E5*G6 -> 4 | F6: =F5*G6 -> 2 | G6: 1
A7: =A6*2 -> 14 | B7: =B6*1 -> 6 | C7: =C6*1.5 -> 0 | D7: =D6*4 -> 16 | E7: =E6*2 -> 8 | F7: =F6*5 -> 10 | G7: =sum(A7:F7) -> 54 | H7: 9
A9: Name | C9: Range | D9: # of attacks | E9: Damage | F9: Armour Piercing | G9: Pts Cost | H9: Total
A10: Orcish Swords | C10: Melee | D10: 4 | E10: 1 | F10: - | G10: 11
C11: Re Roll One Failed Attack Die | G11: 8
A14: Evil, Orcs, Infantry
A15: Base Size: 40mm x 20mm | E15: Total | F15: =sum((G7+G11+G10+G12+G13)*G15) -> 73 | G15: 1 | H15: =F15*H7 -> 657
A17: Orc Heavy Infantry
A18: Movement | B18: Melee Ability | C18: Ranged Ability | D18: Defence | E18: Morale | F18: Wounds | G18: Mod | H18: Qty
A19: 6 | B19: 4 | C19: 10 | D19: 5 | E19: 5 | F19: 2
A20: =A19 -> 6 | B20: =10-B19 -> 6 | C20: =10-C19 -> 0 | D20: =10-D19 -> 5 | E20: =10-E19 -> 5 | F20: =F19 -> 2
A21: =A20*G21 -> 6 | B21: =B20*G21 -> 6 | C21: =C20*G21 -> 0 | D21: =D20*G21 -> 5 | E21: =E20*G21 -> 5 | F21: =F20*G21 -> 2 | G21: 1
A22: =A21*2 -> 12 | B22: =B21*1 -> 6 | C22: =C21*1.5 -> 0 | D22: =D21*4 -> 20 | E22: =E21*2 -> 10 | F22: =F21*5 -> 10 | G22: =sum(A22:F22) -> 58 | H22: 9
A24: Name | C24: Range | D24: # of attacks | E24: Damage | F24: Armour Piercing | G24: Pts Cost | H24: Total
A25: Orcish Swords | C25: Melee | D25: 4 | E25: 1 | F25: - | G25: 11
C26: For Every "0" In The Original Attack Roll You May Reroll One Failed Attack Roll. | G26: 2
A27: Armoured | C27: Reroll One Failed Defence Die | G27: 3
A29: Evil, Orcs, Infantry
A30: Base Size: 40mm x 20mm | E30: Total | F30: =sum((G22+G26+G25+G27+G28)*G30) -> 74 | G30: 1 | H30: =F30*H22 -> 666
A32: Orc Axes
A33: Movement | B33: Melee Ability | C33: Ranged Ability | D33: Defence | E33: Morale | F33: Wounds | G33: Mod | H33: Qty
A34: 7 | B34: 4 | C34: 10 | D34: 6 | E34: 5 | F34: 2
A35: =A34 -> 7 | B35: =10-B34 -> 6 | C35: =10-C34 -> 0 | D35: =10-D34 -> 4 | E35: =10-E34 -> 5 | F35: =F34 -> 2
A36: =A35*G36 -> 7 | B36: =B35*G36 -> 6 | C36: =C35*G36 -> 0 | D36: =D35*G36 -> 4 | E36: =E35*G36 -> 5 | F36: =F35*G36 -> 2 | G36: 1
A37: =A36*2 -> 14 | B37: =B36*1 -> 6 | C37: =C36*1.5 -> 0 | D37: =D36*4 -> 16 | E37: =E36*2 -> 10 | F37: =F36*5 -> 10 | G37: =sum(A37:F37) -> 56 | H37: 9
A39: Name | C39: Range | D39: # of attacks | E39: Damage | F39: Armour Piercing | G39: Pts Cost | H39: Total
A40: Orcish Axes | C40: Melee | D40: 2 | E40: 1 | F40: 2 | G40: 15
C41: For Every "0" In The Original Attack Roll The Defender Must Reroll One Successful Defence Die. | G41: 6
A44: Evil, Orcs, Infantry
A45: Base Size: 40mm x 20mm | E45: Total | F45: =sum((G37+G41+G40+G42+G43)*G45) -> 77 | G45: 1 | H45: =F45*H37 -> 693
A47: Spear Orcs
A48: Movement | B48: Melee Ability | C48: Ranged Ability | D48: Defence | E48: Morale | F48: Wounds | G48: Mod | H48: Qty
A49: 7 | B49: 4 | C49: 10 | D49: 6 | E49: 6 | F49: 2
A50: =A49 -> 7 | B50: =10-B49 -> 6 | C50: =10-C49 -> 0 | D50: =10-D49 -> 4 | E50: =10-E49 -> 4 | F50: =F49 -> 2
A51: =A50*G51 -> 7 | B51: =B50*G51 -> 6 | C51: =C50*G51 -> 0 | D51: =D50*G51 -> 4 | E51: =E50*G51 -> 4 | F51: =F50*G51 -> 2 | G51: 1
A52: =A51*2 -> 14 | B52: =B51*1 -> 6 | C52: =C51*1.5 -> 0 | D52: =D51*4 -> 16 | E52: =E51*2 -> 8 | F52: =F51*5 -> 10 | G52: =sum(A52:F52) -> 54 | H52: 9
...

Sheet Attacks
A1: Attack | B1: Range | C1: Attacks | D1: Damage | E1: Def Mod | F1: Cost
A2: Orcish Swords | B2: 0 | C2: 4 | D2: 1 | E2: 0
B3: =B2/4 -> 0 | C3: =C2*2 -> 8 | D3: =D2*3 -> 3 | E3: =((E2*2)*(C2*D2)) -> 0 | F3: =SUM(B3:E3) -> 11
A5: Attack | B5: Range | C5: Attacks | D5: Damage | E5: Def Mod | F5: Cost
A6: Orcish Axes | B6: 0 | C6: 2 | D6: 1 | E6: 2
B7: =B6/4 -> 0 | C7: =C6*2 -> 4 | D7: =D6*3 -> 3 | E7: =((E6*2)*(C6*D6)) -> 8 | F7: =SUM(B7:E7) -> 15
A9: Attack | B9: Range | C9: Attacks | D9: Damage | E9: Def Mod | F9: Cost
A10: Orcish Spears | B10: 0 | C10: 3 | D10: 1 | E10: 0
B11: =B10/4 -> 0 | C11: =C10*2 -> 6 | D11: =D10*3 -> 3 | E11: =((E10*2)*(C10*D10)) -> 0 | F11: =SUM(B11:E11) -> 9
A13: Attack | B13: Range | C13: Attacks | D13: Damage | E13: Def Mod | F13: Cost
A14: Orcish Bows | B14: 20 | C14: 3 | D14: 1 | E14: 0
B15: =B14/4 -> 5 | C15: =C14*2 -> 6 | D15: =D14*3 -> 3 | E15: =((E14*2)*(C14*D14)) -> 0 | F15: =SUM(B15:E15) -> 14
A17: Attack | B17: Range | C17: Attacks | D17: Damage | E17: Def Mod | F17: Cost
A18: Orcish Knives | B18: 0 | C18: 2 | D18: 1 | E18: 0
B19: =B18/4 -> 0 | C19: =C18*2 -> 4 | D19: =D18*3 -> 3 | E19: =((E18*2)*(C18*D18)) -> 0 | F19: =SUM(B19:E19) -> 7
A21: Attack | B21: Range | C21: Attacks | D21: Damage | E21: Def Mod | F21: Cost
A22: Orcish Bows | B22: 12 | C22: 3 | D22: 1 | E22: 0
B23: =B22/4 -> 3 | C23: =C22*2 -> 6 | D23: =D22*3 -> 3 | E23: =((E22*2)*(C22*D22)) -> 0 | F23: =SUM(B23:E23) -> 12

Sheet Shield Saves
A1: Shield Save Roll (d10) | B1: Success % | C1: Equivalent Def Bonus | D1: Base Point Cost
A2: 8+ | B2: 0.3 | C2: ~ +1.5 Def | D2: 4.5 Points
A3: 7+ | B3: 0.4 | C3: ~ +2.0 Def | D3: 6.0 Points
A4: 6+ | B4: 0.5 | C4: ~ +3.0 Def | D4: 9.0 Points
A5: 5+ | B5: 0.6 | C5: ~ +4.0 Def | D5: 12.0 Points

Sheet Re roll costs
A1: Re-roll Type | B1: Multiplier | C1: Calculation (Multiplier ×2) | D1: Base Value
A2: Melee | B2: 1.0\times | C2: 1.0 \times 2 | D2: 2 Points
A3: Ranged | B3: 1.5\times | C3: 1.5 \times 2 | D3: 3 Points
A4: Defence | B4: 3.0\times | C4: 3.0 \times 2 | D4: 6 Points
A5: Shield Save | B5: 4.5\times | C5: 4.5 \times 2 | D5: 9 Points

Sheet Army Builder
C1: Total Cost | D1: =SUM(D4:D9) -> 2874 | E1: =D1*0.25 -> 718.5
A3: Name | B3: Pts | C3: Qty | D3: Total
A4: =Units!A2 -> Orc Light Infantry | B4: =Units!F15 -> 73 | C4: 6 | D4: =B4*C4 -> 438
A5: =Units!A17 -> Orc Heavy Infantry | B5: =Units!F30 -> 74 | C5: 6 | D5: =B5*C5 -> 444
A6: =Units!A32 -> Orc Axes | B6: =Units!F45 -> 77 | C6: 6 | D6: =B6*C6 -> 462
A7: =Units!A47 -> Spear Orcs | B7: =Units!F60 -> 71 | C7: 6 | D7: =B7*C7 -> 426
A8: =Units!A62 -> Orc Archers | B8: =Units!F75 -> 82.5 | C8: 0 | D8: =B8*C8 -> 0
A9: =Units!A77 -> Orc Warg Rider Skirmishers | B9: =Units!F90 -> 92 | C9: 12 | D9: =B9*C9 -> 1104
